


package net.TelepathicGrunt.UltraAmplified.World.gen.structure;

import java.util.Map;
import java.util.Map.Entry;
import java.util.Random;

import net.TelepathicGrunt.UltraAmplified.Config.UAConfig;
import net.minecraft.block.BlockCauldron;
import net.minecraft.block.BlockColored;
import net.minecraft.block.BlockFlowerPot;
import net.minecraft.block.BlockLever;
import net.minecraft.block.BlockPistonBase;
import net.minecraft.block.BlockPlanks;
import net.minecraft.block.BlockRedstoneRepeater;
import net.minecraft.block.BlockSandStone;
import net.minecraft.block.BlockStairs;
import net.minecraft.block.BlockStoneBrick;
import net.minecraft.block.BlockStoneSlab;
import net.minecraft.block.BlockTripWire;
import net.minecraft.block.BlockTripWireHook;
import net.minecraft.block.BlockVine;
import net.minecraft.block.state.IBlockState;
import net.minecraft.entity.IEntityLivingData;
import net.minecraft.entity.monster.EntityWitch;
import net.minecraft.init.Blocks;
import net.minecraft.init.Items;
import net.minecraft.init.PotionTypes;
import net.minecraft.item.EnumDyeColor;
import net.minecraft.item.ItemStack;
import net.minecraft.nbt.NBTTagCompound;
import net.minecraft.potion.PotionUtils;
import net.minecraft.server.MinecraftServer;
import net.minecraft.tileentity.TileEntity;
import net.minecraft.tileentity.TileEntityBrewingStand;
import net.minecraft.tileentity.TileEntityChest;
import net.minecraft.util.EnumFacing;
import net.minecraft.util.ResourceLocation;
import net.minecraft.util.Rotation;
import net.minecraft.util.math.BlockPos;
import net.minecraft.world.World;
import net.minecraft.world.gen.structure.MapGenStructureIO;
import net.minecraft.world.gen.structure.StructureBoundingBox;
import net.minecraft.world.gen.structure.StructureComponent;
import net.minecraft.world.gen.structure.template.PlacementSettings;
import net.minecraft.world.gen.structure.template.Template;
import net.minecraft.world.gen.structure.template.TemplateManager;
import net.minecraft.world.storage.loot.LootTableList;

public class ComponentScatteredFeaturePiecesUA
{
    public static void registerScatteredFeaturePieces()
    {
        MapGenStructureIO.registerStructureComponent(ComponentScatteredFeaturePiecesUA.DesertPyramid.class, "TeDP");
        MapGenStructureIO.registerStructureComponent(ComponentScatteredFeaturePiecesUA.JunglePyramid.class, "TeJP");
        MapGenStructureIO.registerStructureComponent(ComponentScatteredFeaturePiecesUA.SwampHut.class, "TeSH");
        MapGenStructureIO.registerStructureComponent(ComponentScatteredFeaturePiecesUA.Igloo.class, "Iglu");
    }

    public static class DesertPyramid extends ComponentScatteredFeaturePiecesUA.Feature
    {
        private final boolean[] hasPlacedChest = new boolean[4];

        public DesertPyramid()
        {
        }

        public DesertPyramid(Random p_i2062_1_, int p_i2062_2_, int p_i2062_3_)
        {
            super(p_i2062_1_, p_i2062_2_, 220, p_i2062_3_, 21, 15, 21);
        }

        protected void writeStructureToNBT(NBTTagCompound tagCompound)
        {
            super.writeStructureToNBT(tagCompound);
            tagCompound.setBoolean("hasPlacedChest0", this.hasPlacedChest[0]);
            tagCompound.setBoolean("hasPlacedChest1", this.hasPlacedChest[1]);
            tagCompound.setBoolean("hasPlacedChest2", this.hasPlacedChest[2]);
            tagCompound.setBoolean("hasPlacedChest3", this.hasPlacedChest[3]);
        }

        protected void readStructureFromNBT(NBTTagCompound tagCompound, TemplateManager p_143011_2_)
        {
            super.readStructureFromNBT(tagCompound, p_143011_2_);
            this.hasPlacedChest[0] = tagCompound.getBoolean("hasPlacedChest0");
            this.hasPlacedChest[1] = tagCompound.getBoolean("hasPlacedChest1");
            this.hasPlacedChest[2] = tagCompound.getBoolean("hasPlacedChest2");
            this.hasPlacedChest[3] = tagCompound.getBoolean("hasPlacedChest3");
        }
        
        protected boolean offsetToAverageGroundLevel(World worldIn, StructureBoundingBox structurebb, int yOffset)
        {
            if (this.horizontalPos >= 0)
            {
                return true;
            }
            else
            {
                int i = 0;
                int j = 0;
                BlockPos.MutableBlockPos blockpos$mutableblockpos = new BlockPos.MutableBlockPos();

                for (int k = this.boundingBox.minZ; k <= this.boundingBox.maxZ; ++k)
                {
                    for (int l = this.boundingBox.minX; l <= this.boundingBox.maxX; ++l)
                    {
                        blockpos$mutableblockpos.setPos(l, 64, k);

                        if (structurebb.isVecInside(blockpos$mutableblockpos))
                        {
                        	int height = worldIn.getTopSolidOrLiquidBlock(blockpos$mutableblockpos).getY();
                        	
                        	if(height > 244) {
                        		i += Math.max(244, worldIn.provider.getAverageGroundLevel());
                        	}
                        	else {
                        		i += Math.max(worldIn.getTopSolidOrLiquidBlock(blockpos$mutableblockpos).getY(), worldIn.provider.getAverageGroundLevel());	
                        	}
                        	++j;
                        }
                    }
                }

                if (j == 0)
                {
                    return false;
                }
                else
                {
                    this.horizontalPos = i / j;
                    this.boundingBox.offset(0, this.horizontalPos - this.boundingBox.minY + yOffset, 0);
                    return true;
                }
            }
        }

        public boolean addComponentParts(World worldIn, Random randomIn, StructureBoundingBox structureBoundingBoxIn)
        {
        	if (!this.offsetToAverageGroundLevel(worldIn, structureBoundingBoxIn, 0))
            {
                return false;
            }
            else
            {
        	
            this.fillWithBlocks(worldIn, structureBoundingBoxIn, 0, -4, 0, this.scatteredFeatureSizeX - 1, 0, this.scatteredFeatureSizeZ - 1, Blocks.SANDSTONE.getDefaultState(), Blocks.SANDSTONE.getDefaultState(), false);

            for (int i = 1; i <= 9; ++i)
            {
                this.fillWithBlocks(worldIn, structureBoundingBoxIn, i, i, i, this.scatteredFeatureSizeX - 1 - i, i, this.scatteredFeatureSizeZ - 1 - i, Blocks.SANDSTONE.getDefaultState(), Blocks.SANDSTONE.getDefaultState(), false);
                this.fillWithBlocks(worldIn, structureBoundingBoxIn, i + 1, i, i + 1, this.scatteredFeatureSizeX - 2 - i, i, this.scatteredFeatureSizeZ - 2 - i, Blocks.AIR.getDefaultState(), Blocks.AIR.getDefaultState(), false);
            }

            for (int i2 = 0; i2 < this.scatteredFeatureSizeX; ++i2)
            {
                for (int j = 0; j < this.scatteredFeatureSizeZ; ++j)
                {
                    this.replaceAirAndLiquidDownwards(worldIn, Blocks.SANDSTONE.getDefaultState(), i2, -5, j, structureBoundingBoxIn);
                }
            }

            IBlockState iblockstate1 = Blocks.SANDSTONE_STAIRS.getDefaultState().withProperty(BlockStairs.FACING, EnumFacing.NORTH);
            IBlockState iblockstate2 = Blocks.SANDSTONE_STAIRS.getDefaultState().withProperty(BlockStairs.FACING, EnumFacing.SOUTH);
            IBlockState iblockstate3 = Blocks.SANDSTONE_STAIRS.getDefaultState().withProperty(BlockStairs.FACING, EnumFacing.EAST);
            IBlockState iblockstate = Blocks.SANDSTONE_STAIRS.getDefaultState().withProperty(BlockStairs.FACING, EnumFacing.WEST);
            this.fillWithBlocks(worldIn, structureBoundingBoxIn, 0, 0, 0, 4, 9, 4, Blocks.SANDSTONE.getDefaultState(), Blocks.AIR.getDefaultState(), false);
            this.fillWithBlocks(worldIn, structureBoundingBoxIn, 1, 10, 1, 3, 10, 3, Blocks.SANDSTONE.getDefaultState(), Blocks.SANDSTONE.getDefaultState(), false);
            this.setBlockState(worldIn, iblockstate1, 2, 10, 0, structureBoundingBoxIn);
            this.setBlockState(worldIn, iblockstate2, 2, 10, 4, structureBoundingBoxIn);
            this.setBlockState(worldIn, iblockstate3, 0, 10, 2, structureBoundingBoxIn);
            this.setBlockState(worldIn, iblockstate, 4, 10, 2, structureBoundingBoxIn);
            this.fillWithBlocks(worldIn, structureBoundingBoxIn, this.scatteredFeatureSizeX - 5, 0, 0, this.scatteredFeatureSizeX - 1, 9, 4, Blocks.SANDSTONE.getDefaultState(), Blocks.AIR.getDefaultState(), false);
            this.fillWithBlocks(worldIn, structureBoundingBoxIn, this.scatteredFeatureSizeX - 4, 10, 1, this.scatteredFeatureSizeX - 2, 10, 3, Blocks.SANDSTONE.getDefaultState(), Blocks.SANDSTONE.getDefaultState(), false);
            this.setBlockState(worldIn, iblockstate1, this.scatteredFeatureSizeX - 3, 10, 0, structureBoundingBoxIn);
            this.setBlockState(worldIn, iblockstate2, this.scatteredFeatureSizeX - 3, 10, 4, structureBoundingBoxIn);
            this.setBlockState(worldIn, iblockstate3, this.scatteredFeatureSizeX - 5, 10, 2, structureBoundingBoxIn);
            this.setBlockState(worldIn, iblockstate, this.scatteredFeatureSizeX - 1, 10, 2, structureBoundingBoxIn);
            this.fillWithBlocks(worldIn, structureBoundingBoxIn, 8, 0, 0, 12, 4, 4, Blocks.SANDSTONE.getDefaultState(), Blocks.AIR.getDefaultState(), false);
            this.fillWithBlocks(worldIn, structureBoundingBoxIn, 9, 1, 0, 11, 3, 4, Blocks.AIR.getDefaultState(), Blocks.AIR.getDefaultState(), false);
            this.setBlockState(worldIn, Blocks.SANDSTONE.getDefaultState().withProperty(BlockSandStone.TYPE, BlockSandStone.EnumType.SMOOTH), 9, 1, 1, structureBoundingBoxIn);
            this.setBlockState(worldIn, Blocks.SANDSTONE.getDefaultState().withProperty(BlockSandStone.TYPE, BlockSandStone.EnumType.SMOOTH), 9, 2, 1, structureBoundingBoxIn);
            this.setBlockState(worldIn, Blocks.SANDSTONE.getDefaultState().withProperty(BlockSandStone.TYPE, BlockSandStone.EnumType.SMOOTH), 9, 3, 1, structureBoundingBoxIn);
            this.setBlockState(worldIn, Blocks.SANDSTONE.getDefaultState().withProperty(BlockSandStone.TYPE, BlockSandStone.EnumType.SMOOTH), 10, 3, 1, structureBoundingBoxIn);
            this.setBlockState(worldIn, Blocks.SANDSTONE.getDefaultState().withProperty(BlockSandStone.TYPE, BlockSandStone.EnumType.SMOOTH), 11, 3, 1, structureBoundingBoxIn);
            this.setBlockState(worldIn, Blocks.SANDSTONE.getDefaultState().withProperty(BlockSandStone.TYPE, BlockSandStone.EnumType.SMOOTH), 11, 2, 1, structureBoundingBoxIn);
            this.setBlockState(worldIn, Blocks.SANDSTONE.getDefaultState().withProperty(BlockSandStone.TYPE, BlockSandStone.EnumType.SMOOTH), 11, 1, 1, structureBoundingBoxIn);
            this.fillWithBlocks(worldIn, structureBoundingBoxIn, 4, 1, 1, 8, 3, 3, Blocks.SANDSTONE.getDefaultState(), Blocks.AIR.getDefaultState(), false);
            this.fillWithBlocks(worldIn, structureBoundingBoxIn, 4, 1, 2, 8, 2, 2, Blocks.AIR.getDefaultState(), Blocks.AIR.getDefaultState(), false);
            this.fillWithBlocks(worldIn, structureBoundingBoxIn, 12, 1, 1, 16, 3, 3, Blocks.SANDSTONE.getDefaultState(), Blocks.AIR.getDefaultState(), false);
            this.fillWithBlocks(worldIn, structureBoundingBoxIn, 12, 1, 2, 16, 2, 2, Blocks.AIR.getDefaultState(), Blocks.AIR.getDefaultState(), false);
            this.fillWithBlocks(worldIn, structureBoundingBoxIn, 5, 4, 5, this.scatteredFeatureSizeX - 6, 4, this.scatteredFeatureSizeZ - 6, Blocks.SANDSTONE.getDefaultState(), Blocks.SANDSTONE.getDefaultState(), false);
            this.fillWithBlocks(worldIn, structureBoundingBoxIn, 9, 4, 9, 11, 4, 11, Blocks.AIR.getDefaultState(), Blocks.AIR.getDefaultState(), false);
            this.fillWithBlocks(worldIn, structureBoundingBoxIn, 8, 1, 8, 8, 3, 8, Blocks.SANDSTONE.getDefaultState().withProperty(BlockSandStone.TYPE, BlockSandStone.EnumType.SMOOTH), Blocks.SANDSTONE.getDefaultState().withProperty(BlockSandStone.TYPE, BlockSandStone.EnumType.SMOOTH), false);
            this.fillWithBlocks(worldIn, structureBoundingBoxIn, 12, 1, 8, 12, 3, 8, Blocks.SANDSTONE.getDefaultState().withProperty(BlockSandStone.TYPE, BlockSandStone.EnumType.SMOOTH), Blocks.SANDSTONE.getDefaultState().withProperty(BlockSandStone.TYPE, BlockSandStone.EnumType.SMOOTH), false);
            this.fillWithBlocks(worldIn, structureBoundingBoxIn, 8, 1, 12, 8, 3, 12, Blocks.SANDSTONE.getDefaultState().withProperty(BlockSandStone.TYPE, BlockSandStone.EnumType.SMOOTH), Blocks.SANDSTONE.getDefaultState().withProperty(BlockSandStone.TYPE, BlockSandStone.EnumType.SMOOTH), false);
            this.fillWithBlocks(worldIn, structureBoundingBoxIn, 12, 1, 12, 12, 3, 12, Blocks.SANDSTONE.getDefaultState().withProperty(BlockSandStone.TYPE, BlockSandStone.EnumType.SMOOTH), Blocks.SANDSTONE.getDefaultState().withProperty(BlockSandStone.TYPE, BlockSandStone.EnumType.SMOOTH), false);
            this.fillWithBlocks(worldIn, structureBoundingBoxIn, 1, 1, 5, 4, 4, 11, Blocks.SANDSTONE.getDefaultState(), Blocks.SANDSTONE.getDefaultState(), false);
            this.fillWithBlocks(worldIn, structureBoundingBoxIn, this.scatteredFeatureSizeX - 5, 1, 5, this.scatteredFeatureSizeX - 2, 4, 11, Blocks.SANDSTONE.getDefaultState(), Blocks.SANDSTONE.getDefaultState(), false);
            this.fillWithBlocks(worldIn, structureBoundingBoxIn, 6, 7, 9, 6, 7, 11, Blocks.SANDSTONE.getDefaultState(), Blocks.SANDSTONE.getDefaultState(), false);
            this.fillWithBlocks(worldIn, structureBoundingBoxIn, this.scatteredFeatureSizeX - 7, 7, 9, this.scatteredFeatureSizeX - 7, 7, 11, Blocks.SANDSTONE.getDefaultState(), Blocks.SANDSTONE.getDefaultState(), false);
            this.fillWithBlocks(worldIn, structureBoundingBoxIn, 5, 5, 9, 5, 7, 11, Blocks.SANDSTONE.getDefaultState().withProperty(BlockSandStone.TYPE, BlockSandStone.EnumType.SMOOTH), Blocks.SANDSTONE.getDefaultState().withProperty(BlockSandStone.TYPE, BlockSandStone.EnumType.SMOOTH), false);
            this.fillWithBlocks(worldIn, structureBoundingBoxIn, this.scatteredFeatureSizeX - 6, 5, 9, this.scatteredFeatureSizeX - 6, 7, 11, Blocks.SANDSTONE.getDefaultState().withProperty(BlockSandStone.TYPE, BlockSandStone.EnumType.SMOOTH), Blocks.SANDSTONE.getDefaultState().withProperty(BlockSandStone.TYPE, BlockSandStone.EnumType.SMOOTH), false);
            this.setBlockState(worldIn, Blocks.AIR.getDefaultState(), 5, 5, 10, structureBoundingBoxIn);
            this.setBlockState(worldIn, Blocks.AIR.getDefaultState(), 5, 6, 10, structureBoundingBoxIn);
            this.setBlockState(worldIn, Blocks.AIR.getDefaultState(), 6, 6, 10, structureBoundingBoxIn);
            this.setBlockState(worldIn, Blocks.AIR.getDefaultState(), this.scatteredFeatureSizeX - 6, 5, 10, structureBoundingBoxIn);
            this.setBlockState(worldIn, Blocks.AIR.getDefaultState(), this.scatteredFeatureSizeX - 6, 6, 10, structureBoundingBoxIn);
            this.setBlockState(worldIn, Blocks.AIR.getDefaultState(), this.scatteredFeatureSizeX - 7, 6, 10, structureBoundingBoxIn);
            this.fillWithBlocks(worldIn, structureBoundingBoxIn, 2, 4, 4, 2, 6, 4, Blocks.AIR.getDefaultState(), Blocks.AIR.getDefaultState(), false);
            this.fillWithBlocks(worldIn, structureBoundingBoxIn, this.scatteredFeatureSizeX - 3, 4, 4, this.scatteredFeatureSizeX - 3, 6, 4, Blocks.AIR.getDefaultState(), Blocks.AIR.getDefaultState(), false);
            this.setBlockState(worldIn, iblockstate1, 2, 4, 5, structureBoundingBoxIn);
            this.setBlockState(worldIn, iblockstate1, 2, 3, 4, structureBoundingBoxIn);
            this.setBlockState(worldIn, iblockstate1, this.scatteredFeatureSizeX - 3, 4, 5, structureBoundingBoxIn);
            this.setBlockState(worldIn, iblockstate1, this.scatteredFeatureSizeX - 3, 3, 4, structureBoundingBoxIn);
            this.fillWithBlocks(worldIn, structureBoundingBoxIn, 1, 1, 3, 2, 2, 3, Blocks.SANDSTONE.getDefaultState(), Blocks.SANDSTONE.getDefaultState(), false);
            this.fillWithBlocks(worldIn, structureBoundingBoxIn, this.scatteredFeatureSizeX - 3, 1, 3, this.scatteredFeatureSizeX - 2, 2, 3, Blocks.SANDSTONE.getDefaultState(), Blocks.SANDSTONE.getDefaultState(), false);
            this.setBlockState(worldIn, Blocks.SANDSTONE.getDefaultState(), 1, 1, 2, structureBoundingBoxIn);
            this.setBlockState(worldIn, Blocks.SANDSTONE.getDefaultState(), this.scatteredFeatureSizeX - 2, 1, 2, structureBoundingBoxIn);
            this.setBlockState(worldIn, Blocks.STONE_SLAB.getDefaultState().withProperty(BlockStoneSlab.VARIANT, BlockStoneSlab.EnumType.SAND), 1, 2, 2, structureBoundingBoxIn);
            this.setBlockState(worldIn, Blocks.STONE_SLAB.getDefaultState().withProperty(BlockStoneSlab.VARIANT, BlockStoneSlab.EnumType.SAND), this.scatteredFeatureSizeX - 2, 2, 2, structureBoundingBoxIn);
            this.setBlockState(worldIn, iblockstate, 2, 1, 2, structureBoundingBoxIn);
            this.setBlockState(worldIn, iblockstate3, this.scatteredFeatureSizeX - 3, 1, 2, structureBoundingBoxIn);
            this.fillWithBlocks(worldIn, structureBoundingBoxIn, 4, 3, 5, 4, 3, 18, Blocks.SANDSTONE.getDefaultState(), Blocks.SANDSTONE.getDefaultState(), false);
            this.fillWithBlocks(worldIn, structureBoundingBoxIn, this.scatteredFeatureSizeX - 5, 3, 5, this.scatteredFeatureSizeX - 5, 3, 17, Blocks.SANDSTONE.getDefaultState(), Blocks.SANDSTONE.getDefaultState(), false);
            this.fillWithBlocks(worldIn, structureBoundingBoxIn, 3, 1, 5, 4, 2, 16, Blocks.AIR.getDefaultState(), Blocks.AIR.getDefaultState(), false);
            this.fillWithBlocks(worldIn, structureBoundingBoxIn, this.scatteredFeatureSizeX - 6, 1, 5, this.scatteredFeatureSizeX - 5, 2, 16, Blocks.AIR.getDefaultState(), Blocks.AIR.getDefaultState(), false);

            for (int j1 = 5; j1 <= 17; j1 += 2)
            {
                this.setBlockState(worldIn, Blocks.SANDSTONE.getDefaultState().withProperty(BlockSandStone.TYPE, BlockSandStone.EnumType.SMOOTH), 4, 1, j1, structureBoundingBoxIn);
                this.setBlockState(worldIn, Blocks.SANDSTONE.getDefaultState().withProperty(BlockSandStone.TYPE, BlockSandStone.EnumType.CHISELED), 4, 2, j1, structureBoundingBoxIn);
                this.setBlockState(worldIn, Blocks.SANDSTONE.getDefaultState().withProperty(BlockSandStone.TYPE, BlockSandStone.EnumType.SMOOTH), this.scatteredFeatureSizeX - 5, 1, j1, structureBoundingBoxIn);
                this.setBlockState(worldIn, Blocks.SANDSTONE.getDefaultState().withProperty(BlockSandStone.TYPE, BlockSandStone.EnumType.CHISELED), this.scatteredFeatureSizeX - 5, 2, j1, structureBoundingBoxIn);
            }

            this.setBlockState(worldIn, Blocks.STAINED_HARDENED_CLAY.getDefaultState().withProperty(BlockColored.COLOR, EnumDyeColor.ORANGE), 10, 0, 7, structureBoundingBoxIn);
            this.setBlockState(worldIn, Blocks.STAINED_HARDENED_CLAY.getDefaultState().withProperty(BlockColored.COLOR, EnumDyeColor.ORANGE), 10, 0, 8, structureBoundingBoxIn);
            this.setBlockState(worldIn, Blocks.STAINED_HARDENED_CLAY.getDefaultState().withProperty(BlockColored.COLOR, EnumDyeColor.ORANGE), 9, 0, 9, structureBoundingBoxIn);
            this.setBlockState(worldIn, Blocks.STAINED_HARDENED_CLAY.getDefaultState().withProperty(BlockColored.COLOR, EnumDyeColor.ORANGE), 11, 0, 9, structureBoundingBoxIn);
            this.setBlockState(worldIn, Blocks.STAINED_HARDENED_CLAY.getDefaultState().withProperty(BlockColored.COLOR, EnumDyeColor.ORANGE), 8, 0, 10, structureBoundingBoxIn);
            this.setBlockState(worldIn, Blocks.STAINED_HARDENED_CLAY.getDefaultState().withProperty(BlockColored.COLOR, EnumDyeColor.ORANGE), 12, 0, 10, structureBoundingBoxIn);
            this.setBlockState(worldIn, Blocks.STAINED_HARDENED_CLAY.getDefaultState().withProperty(BlockColored.COLOR, EnumDyeColor.ORANGE), 7, 0, 10, structureBoundingBoxIn);
            this.setBlockState(worldIn, Blocks.STAINED_HARDENED_CLAY.getDefaultState().withProperty(BlockColored.COLOR, EnumDyeColor.ORANGE), 13, 0, 10, structureBoundingBoxIn);
            this.setBlockState(worldIn, Blocks.STAINED_HARDENED_CLAY.getDefaultState().withProperty(BlockColored.COLOR, EnumDyeColor.ORANGE), 9, 0, 11, structureBoundingBoxIn);
            this.setBlockState(worldIn, Blocks.STAINED_HARDENED_CLAY.getDefaultState().withProperty(BlockColored.COLOR, EnumDyeColor.ORANGE), 11, 0, 11, structureBoundingBoxIn);
            this.setBlockState(worldIn, Blocks.STAINED_HARDENED_CLAY.getDefaultState().withProperty(BlockColored.COLOR, EnumDyeColor.ORANGE), 10, 0, 12, structureBoundingBoxIn);
            this.setBlockState(worldIn, Blocks.STAINED_HARDENED_CLAY.getDefaultState().withProperty(BlockColored.COLOR, EnumDyeColor.ORANGE), 10, 0, 13, structureBoundingBoxIn);
            this.setBlockState(worldIn, Blocks.STAINED_HARDENED_CLAY.getDefaultState().withProperty(BlockColored.COLOR, EnumDyeColor.BLUE), 10, 0, 10, structureBoundingBoxIn);

            for (int j2 = 0; j2 <= this.scatteredFeatureSizeX - 1; j2 += this.scatteredFeatureSizeX - 1)
            {
                this.setBlockState(worldIn, Blocks.SANDSTONE.getDefaultState().withProperty(BlockSandStone.TYPE, BlockSandStone.EnumType.SMOOTH), j2, 2, 1, structureBoundingBoxIn);
                this.setBlockState(worldIn, Blocks.STAINED_HARDENED_CLAY.getDefaultState().withProperty(BlockColored.COLOR, EnumDyeColor.ORANGE), j2, 2, 2, structureBoundingBoxIn);
                this.setBlockState(worldIn, Blocks.SANDSTONE.getDefaultState().withProperty(BlockSandStone.TYPE, BlockSandStone.EnumType.SMOOTH), j2, 2, 3, structureBoundingBoxIn);
                this.setBlockState(worldIn, Blocks.SANDSTONE.getDefaultState().withProperty(BlockSandStone.TYPE, BlockSandStone.EnumType.SMOOTH), j2, 3, 1, structureBoundingBoxIn);
                this.setBlockState(worldIn, Blocks.STAINED_HARDENED_CLAY.getDefaultState().withProperty(BlockColored.COLOR, EnumDyeColor.ORANGE), j2, 3, 2, structureBoundingBoxIn);
                this.setBlockState(worldIn, Blocks.SANDSTONE.getDefaultState().withProperty(BlockSandStone.TYPE, BlockSandStone.EnumType.SMOOTH), j2, 3, 3, structureBoundingBoxIn);
                this.setBlockState(worldIn, Blocks.STAINED_HARDENED_CLAY.getDefaultState().withProperty(BlockColored.COLOR, EnumDyeColor.ORANGE), j2, 4, 1, structureBoundingBoxIn);
                this.setBlockState(worldIn, Blocks.SANDSTONE.getDefaultState().withProperty(BlockSandStone.TYPE, BlockSandStone.EnumType.CHISELED), j2, 4, 2, structureBoundingBoxIn);
                this.setBlockState(worldIn, Blocks.STAINED_HARDENED_CLAY.getDefaultState().withProperty(BlockColored.COLOR, EnumDyeColor.ORANGE), j2, 4, 3, structureBoundingBoxIn);
                this.setBlockState(worldIn, Blocks.SANDSTONE.getDefaultState().withProperty(BlockSandStone.TYPE, BlockSandStone.EnumType.SMOOTH), j2, 5, 1, structureBoundingBoxIn);
                this.setBlockState(worldIn, Blocks.STAINED_HARDENED_CLAY.getDefaultState().withProperty(BlockColored.COLOR, EnumDyeColor.ORANGE), j2, 5, 2, structureBoundingBoxIn);
                this.setBlockState(worldIn, Blocks.SANDSTONE.getDefaultState().withProperty(BlockSandStone.TYPE, BlockSandStone.EnumType.SMOOTH), j2, 5, 3, structureBoundingBoxIn);
                this.setBlockState(worldIn, Blocks.STAINED_HARDENED_CLAY.getDefaultState().withProperty(BlockColored.COLOR, EnumDyeColor.ORANGE), j2, 6, 1, structureBoundingBoxIn);
                this.setBlockState(worldIn, Blocks.SANDSTONE.getDefaultState().withProperty(BlockSandStone.TYPE, BlockSandStone.EnumType.CHISELED), j2, 6, 2, structureBoundingBoxIn);
                this.setBlockState(worldIn, Blocks.STAINED_HARDENED_CLAY.getDefaultState().withProperty(BlockColored.COLOR, EnumDyeColor.ORANGE), j2, 6, 3, structureBoundingBoxIn);
                this.setBlockState(worldIn, Blocks.STAINED_HARDENED_CLAY.getDefaultState().withProperty(BlockColored.COLOR, EnumDyeColor.ORANGE), j2, 7, 1, structureBoundingBoxIn);
                this.setBlockState(worldIn, Blocks.STAINED_HARDENED_CLAY.getDefaultState().withProperty(BlockColored.COLOR, EnumDyeColor.ORANGE), j2, 7, 2, structureBoundingBoxIn);
                this.setBlockState(worldIn, Blocks.STAINED_HARDENED_CLAY.getDefaultState().withProperty(BlockColored.COLOR, EnumDyeColor.ORANGE), j2, 7, 3, structureBoundingBoxIn);
                this.setBlockState(worldIn, Blocks.SANDSTONE.getDefaultState().withProperty(BlockSandStone.TYPE, BlockSandStone.EnumType.SMOOTH), j2, 8, 1, structureBoundingBoxIn);
                this.setBlockState(worldIn, Blocks.SANDSTONE.getDefaultState().withProperty(BlockSandStone.TYPE, BlockSandStone.EnumType.SMOOTH), j2, 8, 2, structureBoundingBoxIn);
                this.setBlockState(worldIn, Blocks.SANDSTONE.getDefaultState().withProperty(BlockSandStone.TYPE, BlockSandStone.EnumType.SMOOTH), j2, 8, 3, structureBoundingBoxIn);
            }

            for (int k2 = 2; k2 <= this.scatteredFeatureSizeX - 3; k2 += this.scatteredFeatureSizeX - 3 - 2)
            {
                this.setBlockState(worldIn, Blocks.SANDSTONE.getDefaultState().withProperty(BlockSandStone.TYPE, BlockSandStone.EnumType.SMOOTH), k2 - 1, 2, 0, structureBoundingBoxIn);
                this.setBlockState(worldIn, Blocks.STAINED_HARDENED_CLAY.getDefaultState().withProperty(BlockColored.COLOR, EnumDyeColor.ORANGE), k2, 2, 0, structureBoundingBoxIn);
                this.setBlockState(worldIn, Blocks.SANDSTONE.getDefaultState().withProperty(BlockSandStone.TYPE, BlockSandStone.EnumType.SMOOTH), k2 + 1, 2, 0, structureBoundingBoxIn);
                this.setBlockState(worldIn, Blocks.SANDSTONE.getDefaultState().withProperty(BlockSandStone.TYPE, BlockSandStone.EnumType.SMOOTH), k2 - 1, 3, 0, structureBoundingBoxIn);
                this.setBlockState(worldIn, Blocks.STAINED_HARDENED_CLAY.getDefaultState().withProperty(BlockColored.COLOR, EnumDyeColor.ORANGE), k2, 3, 0, structureBoundingBoxIn);
                this.setBlockState(worldIn, Blocks.SANDSTONE.getDefaultState().withProperty(BlockSandStone.TYPE, BlockSandStone.EnumType.SMOOTH), k2 + 1, 3, 0, structureBoundingBoxIn);
                this.setBlockState(worldIn, Blocks.STAINED_HARDENED_CLAY.getDefaultState().withProperty(BlockColored.COLOR, EnumDyeColor.ORANGE), k2 - 1, 4, 0, structureBoundingBoxIn);
                this.setBlockState(worldIn, Blocks.SANDSTONE.getDefaultState().withProperty(BlockSandStone.TYPE, BlockSandStone.EnumType.CHISELED), k2, 4, 0, structureBoundingBoxIn);
                this.setBlockState(worldIn, Blocks.STAINED_HARDENED_CLAY.getDefaultState().withProperty(BlockColored.COLOR, EnumDyeColor.ORANGE), k2 + 1, 4, 0, structureBoundingBoxIn);
                this.setBlockState(worldIn, Blocks.SANDSTONE.getDefaultState().withProperty(BlockSandStone.TYPE, BlockSandStone.EnumType.SMOOTH), k2 - 1, 5, 0, structureBoundingBoxIn);
                this.setBlockState(worldIn, Blocks.STAINED_HARDENED_CLAY.getDefaultState().withProperty(BlockColored.COLOR, EnumDyeColor.ORANGE), k2, 5, 0, structureBoundingBoxIn);
                this.setBlockState(worldIn, Blocks.SANDSTONE.getDefaultState().withProperty(BlockSandStone.TYPE, BlockSandStone.EnumType.SMOOTH), k2 + 1, 5, 0, structureBoundingBoxIn);
                this.setBlockState(worldIn, Blocks.STAINED_HARDENED_CLAY.getDefaultState().withProperty(BlockColored.COLOR, EnumDyeColor.ORANGE), k2 - 1, 6, 0, structureBoundingBoxIn);
                this.setBlockState(worldIn, Blocks.SANDSTONE.getDefaultState().withProperty(BlockSandStone.TYPE, BlockSandStone.EnumType.CHISELED), k2, 6, 0, structureBoundingBoxIn);
                this.setBlockState(worldIn, Blocks.STAINED_HARDENED_CLAY.getDefaultState().withProperty(BlockColored.COLOR, EnumDyeColor.ORANGE), k2 + 1, 6, 0, structureBoundingBoxIn);
                this.setBlockState(worldIn, Blocks.STAINED_HARDENED_CLAY.getDefaultState().withProperty(BlockColored.COLOR, EnumDyeColor.ORANGE), k2 - 1, 7, 0, structureBoundingBoxIn);
                this.setBlockState(worldIn, Blocks.STAINED_HARDENED_CLAY.getDefaultState().withProperty(BlockColored.COLOR, EnumDyeColor.ORANGE), k2, 7, 0, structureBoundingBoxIn);
                this.setBlockState(worldIn, Blocks.STAINED_HARDENED_CLAY.getDefaultState().withProperty(BlockColored.COLOR, EnumDyeColor.ORANGE), k2 + 1, 7, 0, structureBoundingBoxIn);
                this.setBlockState(worldIn, Blocks.SANDSTONE.getDefaultState().withProperty(BlockSandStone.TYPE, BlockSandStone.EnumType.SMOOTH), k2 - 1, 8, 0, structureBoundingBoxIn);
                this.setBlockState(worldIn, Blocks.SANDSTONE.getDefaultState().withProperty(BlockSandStone.TYPE, BlockSandStone.EnumType.SMOOTH), k2, 8, 0, structureBoundingBoxIn);
                this.setBlockState(worldIn, Blocks.SANDSTONE.getDefaultState().withProperty(BlockSandStone.TYPE, BlockSandStone.EnumType.SMOOTH), k2 + 1, 8, 0, structureBoundingBoxIn);
            }

            this.fillWithBlocks(worldIn, structureBoundingBoxIn, 8, 4, 0, 12, 6, 0, Blocks.SANDSTONE.getDefaultState().withProperty(BlockSandStone.TYPE, BlockSandStone.EnumType.SMOOTH), Blocks.SANDSTONE.getDefaultState().withProperty(BlockSandStone.TYPE, BlockSandStone.EnumType.SMOOTH), false);
            this.setBlockState(worldIn, Blocks.AIR.getDefaultState(), 8, 6, 0, structureBoundingBoxIn);
            this.setBlockState(worldIn, Blocks.AIR.getDefaultState(), 12, 6, 0, structureBoundingBoxIn);
            this.setBlockState(worldIn, Blocks.STAINED_HARDENED_CLAY.getDefaultState().withProperty(BlockColored.COLOR, EnumDyeColor.ORANGE), 9, 5, 0, structureBoundingBoxIn);
            this.setBlockState(worldIn, Blocks.SANDSTONE.getDefaultState().withProperty(BlockSandStone.TYPE, BlockSandStone.EnumType.CHISELED), 10, 5, 0, structureBoundingBoxIn);
            this.setBlockState(worldIn, Blocks.STAINED_HARDENED_CLAY.getDefaultState().withProperty(BlockColored.COLOR, EnumDyeColor.ORANGE), 11, 5, 0, structureBoundingBoxIn);
            this.fillWithBlocks(worldIn, structureBoundingBoxIn, 8, -14, 8, 12, -11, 12, Blocks.SANDSTONE.getDefaultState().withProperty(BlockSandStone.TYPE, BlockSandStone.EnumType.SMOOTH), Blocks.SANDSTONE.getDefaultState().withProperty(BlockSandStone.TYPE, BlockSandStone.EnumType.SMOOTH), false);
            this.fillWithBlocks(worldIn, structureBoundingBoxIn, 8, -10, 8, 12, -10, 12, Blocks.SANDSTONE.getDefaultState().withProperty(BlockSandStone.TYPE, BlockSandStone.EnumType.CHISELED), Blocks.SANDSTONE.getDefaultState().withProperty(BlockSandStone.TYPE, BlockSandStone.EnumType.CHISELED), false);
            this.fillWithBlocks(worldIn, structureBoundingBoxIn, 8, -9, 8, 12, -9, 12, Blocks.SANDSTONE.getDefaultState().withProperty(BlockSandStone.TYPE, BlockSandStone.EnumType.SMOOTH), Blocks.SANDSTONE.getDefaultState().withProperty(BlockSandStone.TYPE, BlockSandStone.EnumType.SMOOTH), false);
            this.fillWithBlocks(worldIn, structureBoundingBoxIn, 8, -8, 8, 12, -1, 12, Blocks.SANDSTONE.getDefaultState(), Blocks.SANDSTONE.getDefaultState(), false);
            this.fillWithBlocks(worldIn, structureBoundingBoxIn, 9, -11, 9, 11, -1, 11, Blocks.AIR.getDefaultState(), Blocks.AIR.getDefaultState(), false);
            this.setBlockState(worldIn, Blocks.STONE_PRESSURE_PLATE.getDefaultState(), 10, -11, 10, structureBoundingBoxIn);
            this.fillWithBlocks(worldIn, structureBoundingBoxIn, 9, -13, 9, 11, -13, 11, Blocks.TNT.getDefaultState(), Blocks.AIR.getDefaultState(), false);
            this.setBlockState(worldIn, Blocks.AIR.getDefaultState(), 8, -11, 10, structureBoundingBoxIn);
            this.setBlockState(worldIn, Blocks.AIR.getDefaultState(), 8, -10, 10, structureBoundingBoxIn);
            this.setBlockState(worldIn, Blocks.SANDSTONE.getDefaultState().withProperty(BlockSandStone.TYPE, BlockSandStone.EnumType.CHISELED), 7, -10, 10, structureBoundingBoxIn);
            this.setBlockState(worldIn, Blocks.SANDSTONE.getDefaultState().withProperty(BlockSandStone.TYPE, BlockSandStone.EnumType.SMOOTH), 7, -11, 10, structureBoundingBoxIn);
            this.setBlockState(worldIn, Blocks.AIR.getDefaultState(), 12, -11, 10, structureBoundingBoxIn);
            this.setBlockState(worldIn, Blocks.AIR.getDefaultState(), 12, -10, 10, structureBoundingBoxIn);
            this.setBlockState(worldIn, Blocks.SANDSTONE.getDefaultState().withProperty(BlockSandStone.TYPE, BlockSandStone.EnumType.CHISELED), 13, -10, 10, structureBoundingBoxIn);
            this.setBlockState(worldIn, Blocks.SANDSTONE.getDefaultState().withProperty(BlockSandStone.TYPE, BlockSandStone.EnumType.SMOOTH), 13, -11, 10, structureBoundingBoxIn);
            this.setBlockState(worldIn, Blocks.AIR.getDefaultState(), 10, -11, 8, structureBoundingBoxIn);
            this.setBlockState(worldIn, Blocks.AIR.getDefaultState(), 10, -10, 8, structureBoundingBoxIn);
            this.setBlockState(worldIn, Blocks.SANDSTONE.getDefaultState().withProperty(BlockSandStone.TYPE, BlockSandStone.EnumType.CHISELED), 10, -10, 7, structureBoundingBoxIn);
            this.setBlockState(worldIn, Blocks.SANDSTONE.getDefaultState().withProperty(BlockSandStone.TYPE, BlockSandStone.EnumType.SMOOTH), 10, -11, 7, structureBoundingBoxIn);
            this.setBlockState(worldIn, Blocks.AIR.getDefaultState(), 10, -11, 12, structureBoundingBoxIn);
            this.setBlockState(worldIn, Blocks.AIR.getDefaultState(), 10, -10, 12, structureBoundingBoxIn);
            this.setBlockState(worldIn, Blocks.SANDSTONE.getDefaultState().withProperty(BlockSandStone.TYPE, BlockSandStone.EnumType.CHISELED), 10, -10, 13, structureBoundingBoxIn);
            this.setBlockState(worldIn, Blocks.SANDSTONE.getDefaultState().withProperty(BlockSandStone.TYPE, BlockSandStone.EnumType.SMOOTH), 10, -11, 13, structureBoundingBoxIn);

            if(UAConfig.StructuresOptions.biomeBasedStructuresOptions.chestGeneration) {
	            for (EnumFacing enumfacing : EnumFacing.Plane.HORIZONTAL)
	            {
	                if (!this.hasPlacedChest[enumfacing.getHorizontalIndex()])
	                {
	                    int k1 = enumfacing.getFrontOffsetX() * 2;
	                    int l1 = enumfacing.getFrontOffsetZ() * 2;
	                    this.hasPlacedChest[enumfacing.getHorizontalIndex()] = this.generateChest(worldIn, structureBoundingBoxIn, randomIn, 10 + k1, -11, 10 + l1, LootTableList.CHESTS_DESERT_PYRAMID);
	                }
	            }
            }
            
            return true;
        }
        }
    }

    abstract static class Feature extends StructureComponent
    {
        protected int scatteredFeatureSizeX;
        protected int scatteredFeatureSizeY;
        protected int scatteredFeatureSizeZ;
        protected int horizontalPos = -1;

        public Feature()
        {
        }

        protected Feature(Random rand, int x, int y, int z, int sizeX, int sizeY, int sizeZ)
        {
            super(0);
            this.scatteredFeatureSizeX = sizeX;
            this.scatteredFeatureSizeY = sizeY;
            this.scatteredFeatureSizeZ = sizeZ;
            this.setCoordBaseMode(EnumFacing.Plane.HORIZONTAL.random(rand));

            if (this.getCoordBaseMode().getAxis() == EnumFacing.Axis.Z)
            {
                this.boundingBox = new StructureBoundingBox(x, 120, z, x + sizeX - 1, y + sizeY - 1, z + sizeZ - 1);
            }
            else
            {
                this.boundingBox = new StructureBoundingBox(x, 120, z, x + sizeZ - 1, y + sizeY - 1, z + sizeX - 1);
            }
        }

        protected void writeStructureToNBT(NBTTagCompound tagCompound)
        {
            tagCompound.setInteger("Width", this.scatteredFeatureSizeX);
            tagCompound.setInteger("Height", this.scatteredFeatureSizeY);
            tagCompound.setInteger("Depth", this.scatteredFeatureSizeZ);
            tagCompound.setInteger("HPos", this.horizontalPos);
        }

        protected void readStructureFromNBT(NBTTagCompound tagCompound, TemplateManager p_143011_2_)
        {
            this.scatteredFeatureSizeX = tagCompound.getInteger("Width");
            this.scatteredFeatureSizeY = tagCompound.getInteger("Height");
            this.scatteredFeatureSizeZ = tagCompound.getInteger("Depth");
            this.horizontalPos = tagCompound.getInteger("HPos");
        }

        protected boolean offsetToAverageGroundLevel(World worldIn, StructureBoundingBox structurebb, int yOffset)
        {
            if (this.horizontalPos >= 0)
            {
                return true;
            }
            else
            {
                int i = 0;
                int j = 0;
                BlockPos.MutableBlockPos blockpos$mutableblockpos = new BlockPos.MutableBlockPos();

                for (int k = this.boundingBox.minZ; k <= this.boundingBox.maxZ; ++k)
                {
                    for (int l = this.boundingBox.minX; l <= this.boundingBox.maxX; ++l)
                    {
                        blockpos$mutableblockpos.setPos(l, 64, k);

                        if (structurebb.isVecInside(blockpos$mutableblockpos))
                        {
                        	int height = worldIn.getTopSolidOrLiquidBlock(blockpos$mutableblockpos).getY();
                        	
                        	if(height > 244) {
                        		i += Math.max(244, worldIn.provider.getAverageGroundLevel());
                        	}
                        	else {
                        		i += Math.max(worldIn.getTopSolidOrLiquidBlock(blockpos$mutableblockpos).getY(), worldIn.provider.getAverageGroundLevel());	
                        	}
                        	++j;
                        }
                    }
                }

                if (j == 0)
                {
                    return false;
                }
                else
                {
                    this.horizontalPos = i / j;
                    this.boundingBox.offset(0, this.horizontalPos - this.boundingBox.minY + yOffset, 0);
                    return true;
                }
            }
        }
    }

    public static class Igloo extends ComponentScatteredFeaturePiecesUA.Feature
    {
        private static final ResourceLocation IGLOO_TOP_ID = new ResourceLocation("igloo/igloo_top");
        private static final ResourceLocation IGLOO_MIDDLE_ID = new ResourceLocation("igloo/igloo_middle");
        private static final ResourceLocation IGLOO_BOTTOM_ID = new ResourceLocation("igloo/igloo_bottom");

        public Igloo()
        {
        }

        public Igloo(Random rand, int x, int z)
        {
            super(rand, x, 220, z, 7, 5, 8);
        }

        public boolean addComponentParts(World worldIn, Random randomIn, StructureBoundingBox structureBoundingBoxIn)
        {
            if (!this.offsetToAverageGroundLevel(worldIn, structureBoundingBoxIn, -1))
            {
                return false;
            }
            else
            {
                StructureBoundingBox structureboundingbox = this.getBoundingBox();
                BlockPos blockpos = new BlockPos(structureboundingbox.minX, structureboundingbox.minY, structureboundingbox.minZ);
                Rotation[] arotation = Rotation.values();
                MinecraftServer minecraftserver = worldIn.getMinecraftServer();
                TemplateManager templatemanager = worldIn.getSaveHandler().getStructureTemplateManager();
                PlacementSettings placementsettings = (new PlacementSettings()).setRotation(arotation[randomIn.nextInt(arotation.length)]).setReplacedBlock(Blocks.STRUCTURE_VOID).setBoundingBox(structureboundingbox);
                Template template = templatemanager.getTemplate(minecraftserver, IGLOO_TOP_ID);
                template.addBlocksToWorldChunk(worldIn, blockpos, placementsettings);

	        
	            Template template1 = templatemanager.getTemplate(minecraftserver, IGLOO_MIDDLE_ID);
	            Template template2 = templatemanager.getTemplate(minecraftserver, IGLOO_BOTTOM_ID);
	            int i = randomIn.nextInt(8) + 4;
	
	            for (int j = 0; j < i; ++j)
	            {
	                BlockPos blockpos1 = template.calculateConnectedPos(placementsettings, new BlockPos(3, -1 - j * 3, 5), placementsettings, new BlockPos(1, 2, 1));
	                template1.addBlocksToWorldChunk(worldIn, blockpos.add(blockpos1), placementsettings);
	            }
	
	            BlockPos blockpos4 = blockpos.add(template.calculateConnectedPos(placementsettings, new BlockPos(3, -1 - i * 3, 5), placementsettings, new BlockPos(3, 5, 7)));
	            template2.addBlocksToWorldChunk(worldIn, blockpos4, placementsettings);
	            Map<BlockPos, String> map = template2.getDataBlocks(blockpos4, placementsettings);
	
	            for (Entry<BlockPos, String> entry : map.entrySet())
	            {
	                if ("chest".equals(entry.getValue()))
	                {
	                    BlockPos blockpos2 = (BlockPos)entry.getKey();
	                    worldIn.setBlockState(blockpos2, Blocks.AIR.getDefaultState(), 3);
	                    TileEntity tileentity = worldIn.getTileEntity(blockpos2.down());
	
	                    if (UAConfig.StructuresOptions.biomeBasedStructuresOptions.chestGeneration && tileentity instanceof TileEntityChest)
	                    {
	                        ((TileEntityChest)tileentity).setLootTable(LootTableList.CHESTS_IGLOO_CHEST, randomIn.nextLong());
	                    }
	                }
                }

                return true;
            }
        }
    }

    public static class JunglePyramid extends ComponentScatteredFeaturePiecesUA.Feature
    {
        private boolean placedMainChest;
        private boolean placedHiddenChest;
        private boolean placedTrap1;
        private boolean placedTrap2;
        private static final ComponentScatteredFeaturePiecesUA.JunglePyramid.Stones junglePyramidsRandomScatteredStones = new ComponentScatteredFeaturePiecesUA.JunglePyramid.Stones();

        public JunglePyramid()
        {
        }

        public JunglePyramid(Random rand, int x, int z)
        {
            super(rand, x, 220, z, 12, 10, 15);
        }

        protected void writeStructureToNBT(NBTTagCompound tagCompound)
        {
            super.writeStructureToNBT(tagCompound);
            tagCompound.setBoolean("placedMainChest", this.placedMainChest);
            tagCompound.setBoolean("placedHiddenChest", this.placedHiddenChest);
            tagCompound.setBoolean("placedTrap1", this.placedTrap1);
            tagCompound.setBoolean("placedTrap2", this.placedTrap2);
        }

        protected void readStructureFromNBT(NBTTagCompound tagCompound, TemplateManager p_143011_2_)
        {
            super.readStructureFromNBT(tagCompound, p_143011_2_);
            this.placedMainChest = tagCompound.getBoolean("placedMainChest");
            this.placedHiddenChest = tagCompound.getBoolean("placedHiddenChest");
            this.placedTrap1 = tagCompound.getBoolean("placedTrap1");
            this.placedTrap2 = tagCompound.getBoolean("placedTrap2");
        }

        public boolean addComponentParts(World worldIn, Random randomIn, StructureBoundingBox structureBoundingBoxIn)
        {
            if (!this.offsetToAverageGroundLevel(worldIn, structureBoundingBoxIn, 0))
            {
                return false;
            }
            else
            {
                this.fillWithRandomizedBlocks(worldIn, structureBoundingBoxIn, 0, -4, 0, this.scatteredFeatureSizeX - 1, 0, this.scatteredFeatureSizeZ - 1, false, randomIn, junglePyramidsRandomScatteredStones);
                this.fillWithRandomizedBlocks(worldIn, structureBoundingBoxIn, 2, 1, 2, 9, 2, 2, false, randomIn, junglePyramidsRandomScatteredStones);
                this.fillWithRandomizedBlocks(worldIn, structureBoundingBoxIn, 2, 1, 12, 9, 2, 12, false, randomIn, junglePyramidsRandomScatteredStones);
                this.fillWithRandomizedBlocks(worldIn, structureBoundingBoxIn, 2, 1, 3, 2, 2, 11, false, randomIn, junglePyramidsRandomScatteredStones);
                this.fillWithRandomizedBlocks(worldIn, structureBoundingBoxIn, 9, 1, 3, 9, 2, 11, false, randomIn, junglePyramidsRandomScatteredStones);
                this.fillWithRandomizedBlocks(worldIn, structureBoundingBoxIn, 1, 3, 1, 10, 6, 1, false, randomIn, junglePyramidsRandomScatteredStones);
                this.fillWithRandomizedBlocks(worldIn, structureBoundingBoxIn, 1, 3, 13, 10, 6, 13, false, randomIn, junglePyramidsRandomScatteredStones);
                this.fillWithRandomizedBlocks(worldIn, structureBoundingBoxIn, 1, 3, 2, 1, 6, 12, false, randomIn, junglePyramidsRandomScatteredStones);
                this.fillWithRandomizedBlocks(worldIn, structureBoundingBoxIn, 10, 3, 2, 10, 6, 12, false, randomIn, junglePyramidsRandomScatteredStones);
                this.fillWithRandomizedBlocks(worldIn, structureBoundingBoxIn, 2, 3, 2, 9, 3, 12, false, randomIn, junglePyramidsRandomScatteredStones);
                this.fillWithRandomizedBlocks(worldIn, structureBoundingBoxIn, 2, 6, 2, 9, 6, 12, false, randomIn, junglePyramidsRandomScatteredStones);
                this.fillWithRandomizedBlocks(worldIn, structureBoundingBoxIn, 3, 7, 3, 8, 7, 11, false, randomIn, junglePyramidsRandomScatteredStones);
                this.fillWithRandomizedBlocks(worldIn, structureBoundingBoxIn, 4, 8, 4, 7, 8, 10, false, randomIn, junglePyramidsRandomScatteredStones);
                this.fillWithAir(worldIn, structureBoundingBoxIn, 3, 1, 3, 8, 2, 11);
                this.fillWithAir(worldIn, structureBoundingBoxIn, 4, 3, 6, 7, 3, 9);
                this.fillWithAir(worldIn, structureBoundingBoxIn, 2, 4, 2, 9, 5, 12);
                this.fillWithAir(worldIn, structureBoundingBoxIn, 4, 6, 5, 7, 6, 9);
                this.fillWithAir(worldIn, structureBoundingBoxIn, 5, 7, 6, 6, 7, 8);
                this.fillWithAir(worldIn, structureBoundingBoxIn, 5, 1, 2, 6, 2, 2);
                this.fillWithAir(worldIn, structureBoundingBoxIn, 5, 2, 12, 6, 2, 12);
                this.fillWithAir(worldIn, structureBoundingBoxIn, 5, 5, 1, 6, 5, 1);
                this.fillWithAir(worldIn, structureBoundingBoxIn, 5, 5, 13, 6, 5, 13);
                this.setBlockState(worldIn, Blocks.AIR.getDefaultState(), 1, 5, 5, structureBoundingBoxIn);
                this.setBlockState(worldIn, Blocks.AIR.getDefaultState(), 10, 5, 5, structureBoundingBoxIn);
                this.setBlockState(worldIn, Blocks.AIR.getDefaultState(), 1, 5, 9, structureBoundingBoxIn);
                this.setBlockState(worldIn, Blocks.AIR.getDefaultState(), 10, 5, 9, structureBoundingBoxIn);

                for (int i = 0; i <= 14; i += 14)
                {
                    this.fillWithRandomizedBlocks(worldIn, structureBoundingBoxIn, 2, 4, i, 2, 5, i, false, randomIn, junglePyramidsRandomScatteredStones);
                    this.fillWithRandomizedBlocks(worldIn, structureBoundingBoxIn, 4, 4, i, 4, 5, i, false, randomIn, junglePyramidsRandomScatteredStones);
                    this.fillWithRandomizedBlocks(worldIn, structureBoundingBoxIn, 7, 4, i, 7, 5, i, false, randomIn, junglePyramidsRandomScatteredStones);
                    this.fillWithRandomizedBlocks(worldIn, structureBoundingBoxIn, 9, 4, i, 9, 5, i, false, randomIn, junglePyramidsRandomScatteredStones);
                }

                this.fillWithRandomizedBlocks(worldIn, structureBoundingBoxIn, 5, 6, 0, 6, 6, 0, false, randomIn, junglePyramidsRandomScatteredStones);

                for (int l = 0; l <= 11; l += 11)
                {
                    for (int j = 2; j <= 12; j += 2)
                    {
                        this.fillWithRandomizedBlocks(worldIn, structureBoundingBoxIn, l, 4, j, l, 5, j, false, randomIn, junglePyramidsRandomScatteredStones);
                    }

                    this.fillWithRandomizedBlocks(worldIn, structureBoundingBoxIn, l, 6, 5, l, 6, 5, false, randomIn, junglePyramidsRandomScatteredStones);
                    this.fillWithRandomizedBlocks(worldIn, structureBoundingBoxIn, l, 6, 9, l, 6, 9, false, randomIn, junglePyramidsRandomScatteredStones);
                }

                this.fillWithRandomizedBlocks(worldIn, structureBoundingBoxIn, 2, 7, 2, 2, 9, 2, false, randomIn, junglePyramidsRandomScatteredStones);
                this.fillWithRandomizedBlocks(worldIn, structureBoundingBoxIn, 9, 7, 2, 9, 9, 2, false, randomIn, junglePyramidsRandomScatteredStones);
                this.fillWithRandomizedBlocks(worldIn, structureBoundingBoxIn, 2, 7, 12, 2, 9, 12, false, randomIn, junglePyramidsRandomScatteredStones);
                this.fillWithRandomizedBlocks(worldIn, structureBoundingBoxIn, 9, 7, 12, 9, 9, 12, false, randomIn, junglePyramidsRandomScatteredStones);
                this.fillWithRandomizedBlocks(worldIn, structureBoundingBoxIn, 4, 9, 4, 4, 9, 4, false, randomIn, junglePyramidsRandomScatteredStones);
                this.fillWithRandomizedBlocks(worldIn, structureBoundingBoxIn, 7, 9, 4, 7, 9, 4, false, randomIn, junglePyramidsRandomScatteredStones);
                this.fillWithRandomizedBlocks(worldIn, structureBoundingBoxIn, 4, 9, 10, 4, 9, 10, false, randomIn, junglePyramidsRandomScatteredStones);
                this.fillWithRandomizedBlocks(worldIn, structureBoundingBoxIn, 7, 9, 10, 7, 9, 10, false, randomIn, junglePyramidsRandomScatteredStones);
                this.fillWithRandomizedBlocks(worldIn, structureBoundingBoxIn, 5, 9, 7, 6, 9, 7, false, randomIn, junglePyramidsRandomScatteredStones);
                IBlockState iblockstate2 = Blocks.STONE_STAIRS.getDefaultState().withProperty(BlockStairs.FACING, EnumFacing.EAST);
                IBlockState iblockstate3 = Blocks.STONE_STAIRS.getDefaultState().withProperty(BlockStairs.FACING, EnumFacing.WEST);
                IBlockState iblockstate = Blocks.STONE_STAIRS.getDefaultState().withProperty(BlockStairs.FACING, EnumFacing.SOUTH);
                IBlockState iblockstate1 = Blocks.STONE_STAIRS.getDefaultState().withProperty(BlockStairs.FACING, EnumFacing.NORTH);
                this.setBlockState(worldIn, iblockstate1, 5, 9, 6, structureBoundingBoxIn);
                this.setBlockState(worldIn, iblockstate1, 6, 9, 6, structureBoundingBoxIn);
                this.setBlockState(worldIn, iblockstate, 5, 9, 8, structureBoundingBoxIn);
                this.setBlockState(worldIn, iblockstate, 6, 9, 8, structureBoundingBoxIn);
                this.setBlockState(worldIn, iblockstate1, 4, 0, 0, structureBoundingBoxIn);
                this.setBlockState(worldIn, iblockstate1, 5, 0, 0, structureBoundingBoxIn);
                this.setBlockState(worldIn, iblockstate1, 6, 0, 0, structureBoundingBoxIn);
                this.setBlockState(worldIn, iblockstate1, 7, 0, 0, structureBoundingBoxIn);
                this.setBlockState(worldIn, iblockstate1, 4, 1, 8, structureBoundingBoxIn);
                this.setBlockState(worldIn, iblockstate1, 4, 2, 9, structureBoundingBoxIn);
                this.setBlockState(worldIn, iblockstate1, 4, 3, 10, structureBoundingBoxIn);
                this.setBlockState(worldIn, iblockstate1, 7, 1, 8, structureBoundingBoxIn);
                this.setBlockState(worldIn, iblockstate1, 7, 2, 9, structureBoundingBoxIn);
                this.setBlockState(worldIn, iblockstate1, 7, 3, 10, structureBoundingBoxIn);
                this.fillWithRandomizedBlocks(worldIn, structureBoundingBoxIn, 4, 1, 9, 4, 1, 9, false, randomIn, junglePyramidsRandomScatteredStones);
                this.fillWithRandomizedBlocks(worldIn, structureBoundingBoxIn, 7, 1, 9, 7, 1, 9, false, randomIn, junglePyramidsRandomScatteredStones);
                this.fillWithRandomizedBlocks(worldIn, structureBoundingBoxIn, 4, 1, 10, 7, 2, 10, false, randomIn, junglePyramidsRandomScatteredStones);
                this.fillWithRandomizedBlocks(worldIn, structureBoundingBoxIn, 5, 4, 5, 6, 4, 5, false, randomIn, junglePyramidsRandomScatteredStones);
                this.setBlockState(worldIn, iblockstate2, 4, 4, 5, structureBoundingBoxIn);
                this.setBlockState(worldIn, iblockstate3, 7, 4, 5, structureBoundingBoxIn);

                for (int k = 0; k < 4; ++k)
                {
                    this.setBlockState(worldIn, iblockstate, 5, 0 - k, 6 + k, structureBoundingBoxIn);
                    this.setBlockState(worldIn, iblockstate, 6, 0 - k, 6 + k, structureBoundingBoxIn);
                    this.fillWithAir(worldIn, structureBoundingBoxIn, 5, 0 - k, 7 + k, 6, 0 - k, 9 + k);
                }

                this.fillWithAir(worldIn, structureBoundingBoxIn, 1, -3, 12, 10, -1, 13);
                this.fillWithAir(worldIn, structureBoundingBoxIn, 1, -3, 1, 3, -1, 13);
                this.fillWithAir(worldIn, structureBoundingBoxIn, 1, -3, 1, 9, -1, 5);

                for (int i1 = 1; i1 <= 13; i1 += 2)
                {
                    this.fillWithRandomizedBlocks(worldIn, structureBoundingBoxIn, 1, -3, i1, 1, -2, i1, false, randomIn, junglePyramidsRandomScatteredStones);
                }

                for (int j1 = 2; j1 <= 12; j1 += 2)
                {
                    this.fillWithRandomizedBlocks(worldIn, structureBoundingBoxIn, 1, -1, j1, 3, -1, j1, false, randomIn, junglePyramidsRandomScatteredStones);
                }

                this.fillWithRandomizedBlocks(worldIn, structureBoundingBoxIn, 2, -2, 1, 5, -2, 1, false, randomIn, junglePyramidsRandomScatteredStones);
                this.fillWithRandomizedBlocks(worldIn, structureBoundingBoxIn, 7, -2, 1, 9, -2, 1, false, randomIn, junglePyramidsRandomScatteredStones);
                this.fillWithRandomizedBlocks(worldIn, structureBoundingBoxIn, 6, -3, 1, 6, -3, 1, false, randomIn, junglePyramidsRandomScatteredStones);
                this.fillWithRandomizedBlocks(worldIn, structureBoundingBoxIn, 6, -1, 1, 6, -1, 1, false, randomIn, junglePyramidsRandomScatteredStones);
                this.setBlockState(worldIn, Blocks.TRIPWIRE_HOOK.getDefaultState().withProperty(BlockTripWireHook.FACING, EnumFacing.EAST).withProperty(BlockTripWireHook.ATTACHED, Boolean.valueOf(true)), 1, -3, 8, structureBoundingBoxIn);
                this.setBlockState(worldIn, Blocks.TRIPWIRE_HOOK.getDefaultState().withProperty(BlockTripWireHook.FACING, EnumFacing.WEST).withProperty(BlockTripWireHook.ATTACHED, Boolean.valueOf(true)), 4, -3, 8, structureBoundingBoxIn);
                this.setBlockState(worldIn, Blocks.TRIPWIRE.getDefaultState().withProperty(BlockTripWire.ATTACHED, Boolean.valueOf(true)), 2, -3, 8, structureBoundingBoxIn);
                this.setBlockState(worldIn, Blocks.TRIPWIRE.getDefaultState().withProperty(BlockTripWire.ATTACHED, Boolean.valueOf(true)), 3, -3, 8, structureBoundingBoxIn);
                this.setBlockState(worldIn, Blocks.REDSTONE_WIRE.getDefaultState(), 5, -3, 7, structureBoundingBoxIn);
                this.setBlockState(worldIn, Blocks.REDSTONE_WIRE.getDefaultState(), 5, -3, 6, structureBoundingBoxIn);
                this.setBlockState(worldIn, Blocks.REDSTONE_WIRE.getDefaultState(), 5, -3, 5, structureBoundingBoxIn);
                this.setBlockState(worldIn, Blocks.REDSTONE_WIRE.getDefaultState(), 5, -3, 4, structureBoundingBoxIn);
                this.setBlockState(worldIn, Blocks.REDSTONE_WIRE.getDefaultState(), 5, -3, 3, structureBoundingBoxIn);
                this.setBlockState(worldIn, Blocks.REDSTONE_WIRE.getDefaultState(), 5, -3, 2, structureBoundingBoxIn);
                this.setBlockState(worldIn, Blocks.REDSTONE_WIRE.getDefaultState(), 5, -3, 1, structureBoundingBoxIn);
                this.setBlockState(worldIn, Blocks.REDSTONE_WIRE.getDefaultState(), 4, -3, 1, structureBoundingBoxIn);
                this.setBlockState(worldIn, Blocks.MOSSY_COBBLESTONE.getDefaultState(), 3, -3, 1, structureBoundingBoxIn);

                if (!this.placedTrap1)
                {
                    this.placedTrap1 = this.createDispenser(worldIn, structureBoundingBoxIn, randomIn, 3, -2, 1, EnumFacing.NORTH, LootTableList.CHESTS_JUNGLE_TEMPLE_DISPENSER);
                }

                this.setBlockState(worldIn, Blocks.VINE.getDefaultState().withProperty(BlockVine.SOUTH, Boolean.valueOf(true)), 3, -2, 2, structureBoundingBoxIn);
                this.setBlockState(worldIn, Blocks.TRIPWIRE_HOOK.getDefaultState().withProperty(BlockTripWireHook.FACING, EnumFacing.NORTH).withProperty(BlockTripWireHook.ATTACHED, Boolean.valueOf(true)), 7, -3, 1, structureBoundingBoxIn);
                this.setBlockState(worldIn, Blocks.TRIPWIRE_HOOK.getDefaultState().withProperty(BlockTripWireHook.FACING, EnumFacing.SOUTH).withProperty(BlockTripWireHook.ATTACHED, Boolean.valueOf(true)), 7, -3, 5, structureBoundingBoxIn);
                this.setBlockState(worldIn, Blocks.TRIPWIRE.getDefaultState().withProperty(BlockTripWire.ATTACHED, Boolean.valueOf(true)), 7, -3, 2, structureBoundingBoxIn);
                this.setBlockState(worldIn, Blocks.TRIPWIRE.getDefaultState().withProperty(BlockTripWire.ATTACHED, Boolean.valueOf(true)), 7, -3, 3, structureBoundingBoxIn);
                this.setBlockState(worldIn, Blocks.TRIPWIRE.getDefaultState().withProperty(BlockTripWire.ATTACHED, Boolean.valueOf(true)), 7, -3, 4, structureBoundingBoxIn);
                this.setBlockState(worldIn, Blocks.REDSTONE_WIRE.getDefaultState(), 8, -3, 6, structureBoundingBoxIn);
                this.setBlockState(worldIn, Blocks.REDSTONE_WIRE.getDefaultState(), 9, -3, 6, structureBoundingBoxIn);
                this.setBlockState(worldIn, Blocks.REDSTONE_WIRE.getDefaultState(), 9, -3, 5, structureBoundingBoxIn);
                this.setBlockState(worldIn, Blocks.MOSSY_COBBLESTONE.getDefaultState(), 9, -3, 4, structureBoundingBoxIn);
                this.setBlockState(worldIn, Blocks.REDSTONE_WIRE.getDefaultState(), 9, -2, 4, structureBoundingBoxIn);

                if (!this.placedTrap2)
                {
                    this.placedTrap2 = this.createDispenser(worldIn, structureBoundingBoxIn, randomIn, 9, -2, 3, EnumFacing.WEST, LootTableList.CHESTS_JUNGLE_TEMPLE_DISPENSER);
                }

                this.setBlockState(worldIn, Blocks.VINE.getDefaultState().withProperty(BlockVine.EAST, Boolean.valueOf(true)), 8, -1, 3, structureBoundingBoxIn);
                this.setBlockState(worldIn, Blocks.VINE.getDefaultState().withProperty(BlockVine.EAST, Boolean.valueOf(true)), 8, -2, 3, structureBoundingBoxIn);

                if (UAConfig.StructuresOptions.biomeBasedStructuresOptions.chestGeneration && !this.placedMainChest)
                {
                    this.placedMainChest = this.generateChest(worldIn, structureBoundingBoxIn, randomIn, 8, -3, 3, LootTableList.CHESTS_JUNGLE_TEMPLE);
                }

                this.setBlockState(worldIn, Blocks.MOSSY_COBBLESTONE.getDefaultState(), 9, -3, 2, structureBoundingBoxIn);
                this.setBlockState(worldIn, Blocks.MOSSY_COBBLESTONE.getDefaultState(), 8, -3, 1, structureBoundingBoxIn);
                this.setBlockState(worldIn, Blocks.MOSSY_COBBLESTONE.getDefaultState(), 4, -3, 5, structureBoundingBoxIn);
                this.setBlockState(worldIn, Blocks.MOSSY_COBBLESTONE.getDefaultState(), 5, -2, 5, structureBoundingBoxIn);
                this.setBlockState(worldIn, Blocks.MOSSY_COBBLESTONE.getDefaultState(), 5, -1, 5, structureBoundingBoxIn);
                this.setBlockState(worldIn, Blocks.MOSSY_COBBLESTONE.getDefaultState(), 6, -3, 5, structureBoundingBoxIn);
                this.setBlockState(worldIn, Blocks.MOSSY_COBBLESTONE.getDefaultState(), 7, -2, 5, structureBoundingBoxIn);
                this.setBlockState(worldIn, Blocks.MOSSY_COBBLESTONE.getDefaultState(), 7, -1, 5, structureBoundingBoxIn);
                this.setBlockState(worldIn, Blocks.MOSSY_COBBLESTONE.getDefaultState(), 8, -3, 5, structureBoundingBoxIn);
                this.fillWithRandomizedBlocks(worldIn, structureBoundingBoxIn, 9, -1, 1, 9, -1, 5, false, randomIn, junglePyramidsRandomScatteredStones);
                this.fillWithAir(worldIn, structureBoundingBoxIn, 8, -3, 8, 10, -1, 10);
                this.setBlockState(worldIn, Blocks.STONEBRICK.getDefaultState().withProperty(BlockStoneBrick.VARIANT, BlockStoneBrick.EnumType.CHISELED), 8, -2, 11, structureBoundingBoxIn);
                this.setBlockState(worldIn, Blocks.STONEBRICK.getDefaultState().withProperty(BlockStoneBrick.VARIANT, BlockStoneBrick.EnumType.CHISELED), 9, -2, 11, structureBoundingBoxIn);
                this.setBlockState(worldIn, Blocks.STONEBRICK.getDefaultState().withProperty(BlockStoneBrick.VARIANT, BlockStoneBrick.EnumType.CHISELED), 10, -2, 11, structureBoundingBoxIn);
                IBlockState iblockstate4 = Blocks.LEVER.getDefaultState().withProperty(BlockLever.FACING, BlockLever.EnumOrientation.NORTH);
                this.setBlockState(worldIn, iblockstate4, 8, -2, 12, structureBoundingBoxIn);
                this.setBlockState(worldIn, iblockstate4, 9, -2, 12, structureBoundingBoxIn);
                this.setBlockState(worldIn, iblockstate4, 10, -2, 12, structureBoundingBoxIn);
                this.fillWithRandomizedBlocks(worldIn, structureBoundingBoxIn, 8, -3, 8, 8, -3, 10, false, randomIn, junglePyramidsRandomScatteredStones);
                this.fillWithRandomizedBlocks(worldIn, structureBoundingBoxIn, 10, -3, 8, 10, -3, 10, false, randomIn, junglePyramidsRandomScatteredStones);
                this.setBlockState(worldIn, Blocks.MOSSY_COBBLESTONE.getDefaultState(), 10, -2, 9, structureBoundingBoxIn);
                this.setBlockState(worldIn, Blocks.REDSTONE_WIRE.getDefaultState(), 8, -2, 9, structureBoundingBoxIn);
                this.setBlockState(worldIn, Blocks.REDSTONE_WIRE.getDefaultState(), 8, -2, 10, structureBoundingBoxIn);
                this.setBlockState(worldIn, Blocks.REDSTONE_WIRE.getDefaultState(), 10, -1, 9, structureBoundingBoxIn);
                this.setBlockState(worldIn, Blocks.STICKY_PISTON.getDefaultState().withProperty(BlockPistonBase.FACING, EnumFacing.UP), 9, -2, 8, structureBoundingBoxIn);
                this.setBlockState(worldIn, Blocks.STICKY_PISTON.getDefaultState().withProperty(BlockPistonBase.FACING, EnumFacing.WEST), 10, -2, 8, structureBoundingBoxIn);
                this.setBlockState(worldIn, Blocks.STICKY_PISTON.getDefaultState().withProperty(BlockPistonBase.FACING, EnumFacing.WEST), 10, -1, 8, structureBoundingBoxIn);
                this.setBlockState(worldIn, Blocks.UNPOWERED_REPEATER.getDefaultState().withProperty(BlockRedstoneRepeater.FACING, EnumFacing.NORTH), 10, -2, 10, structureBoundingBoxIn);

                if (UAConfig.StructuresOptions.biomeBasedStructuresOptions.chestGeneration && !this.placedHiddenChest)
                {
                    this.placedHiddenChest = this.generateChest(worldIn, structureBoundingBoxIn, randomIn, 9, -3, 10, LootTableList.CHESTS_JUNGLE_TEMPLE);
                }

                return true;
            }
        }

        static class Stones extends StructureComponent.BlockSelector
        {
            private Stones()
            {
            }

            public void selectBlocks(Random rand, int x, int y, int z, boolean p_75062_5_)
            {
                if (rand.nextFloat() < 0.4F)
                {
                    this.blockstate = Blocks.COBBLESTONE.getDefaultState();
                }
                else
                {
                    this.blockstate = Blocks.MOSSY_COBBLESTONE.getDefaultState();
                }
            }
        }
    }

    public static class SwampHut extends ComponentScatteredFeaturePiecesUA.Feature
    {
        private boolean hasWitch;

        public SwampHut()
        {
        }

        public SwampHut(Random p_i2066_1_, int p_i2066_2_, int p_i2066_3_)
        {
            super(p_i2066_1_, p_i2066_2_, 220, p_i2066_3_, 7, 7, 9);
        }

        protected void writeStructureToNBT(NBTTagCompound tagCompound)
        {
            super.writeStructureToNBT(tagCompound);
            tagCompound.setBoolean("Witch", this.hasWitch);
        }

        protected void readStructureFromNBT(NBTTagCompound tagCompound, TemplateManager p_143011_2_)
        {
            super.readStructureFromNBT(tagCompound, p_143011_2_);
            this.hasWitch = tagCompound.getBoolean("Witch");
        }

        public boolean addComponentParts(World worldIn, Random random, StructureBoundingBox structureBoundingBoxIn)
        {
            if (!this.offsetToAverageGroundLevel(worldIn, structureBoundingBoxIn, 0))
            {
                return false;
            }
            else
            {
                this.fillWithBlocks(worldIn, structureBoundingBoxIn, 1, 1, 1, 5, 1, 7, Blocks.PLANKS.getDefaultState().withProperty(BlockPlanks.VARIANT, BlockPlanks.EnumType.SPRUCE), Blocks.PLANKS.getDefaultState().withProperty(BlockPlanks.VARIANT, BlockPlanks.EnumType.SPRUCE), false);
                this.fillWithBlocks(worldIn, structureBoundingBoxIn, 1, 4, 2, 5, 4, 7, Blocks.PLANKS.getDefaultState().withProperty(BlockPlanks.VARIANT, BlockPlanks.EnumType.SPRUCE), Blocks.PLANKS.getDefaultState().withProperty(BlockPlanks.VARIANT, BlockPlanks.EnumType.SPRUCE), false);
                this.fillWithBlocks(worldIn, structureBoundingBoxIn, 2, 1, 0, 4, 1, 0, Blocks.PLANKS.getDefaultState().withProperty(BlockPlanks.VARIANT, BlockPlanks.EnumType.SPRUCE), Blocks.PLANKS.getDefaultState().withProperty(BlockPlanks.VARIANT, BlockPlanks.EnumType.SPRUCE), false);
                this.fillWithBlocks(worldIn, structureBoundingBoxIn, 2, 2, 2, 3, 3, 2, Blocks.PLANKS.getDefaultState().withProperty(BlockPlanks.VARIANT, BlockPlanks.EnumType.SPRUCE), Blocks.PLANKS.getDefaultState().withProperty(BlockPlanks.VARIANT, BlockPlanks.EnumType.SPRUCE), false);
                this.fillWithBlocks(worldIn, structureBoundingBoxIn, 1, 2, 3, 1, 3, 6, Blocks.PLANKS.getDefaultState().withProperty(BlockPlanks.VARIANT, BlockPlanks.EnumType.SPRUCE), Blocks.PLANKS.getDefaultState().withProperty(BlockPlanks.VARIANT, BlockPlanks.EnumType.SPRUCE), false);
                this.fillWithBlocks(worldIn, structureBoundingBoxIn, 5, 2, 3, 5, 3, 6, Blocks.PLANKS.getDefaultState().withProperty(BlockPlanks.VARIANT, BlockPlanks.EnumType.SPRUCE), Blocks.PLANKS.getDefaultState().withProperty(BlockPlanks.VARIANT, BlockPlanks.EnumType.SPRUCE), false);
                this.fillWithBlocks(worldIn, structureBoundingBoxIn, 2, 2, 7, 4, 3, 7, Blocks.PLANKS.getDefaultState().withProperty(BlockPlanks.VARIANT, BlockPlanks.EnumType.SPRUCE), Blocks.PLANKS.getDefaultState().withProperty(BlockPlanks.VARIANT, BlockPlanks.EnumType.SPRUCE), false);
                this.fillWithBlocks(worldIn, structureBoundingBoxIn, 1, 0, 2, 1, 3, 2, Blocks.LOG.getDefaultState(), Blocks.LOG.getDefaultState(), false);
                this.fillWithBlocks(worldIn, structureBoundingBoxIn, 5, 0, 2, 5, 3, 2, Blocks.LOG.getDefaultState(), Blocks.LOG.getDefaultState(), false);
                this.fillWithBlocks(worldIn, structureBoundingBoxIn, 1, 0, 7, 1, 3, 7, Blocks.LOG.getDefaultState(), Blocks.LOG.getDefaultState(), false);
                this.fillWithBlocks(worldIn, structureBoundingBoxIn, 5, 0, 7, 5, 3, 7, Blocks.LOG.getDefaultState(), Blocks.LOG.getDefaultState(), false);
                this.setBlockState(worldIn, Blocks.OAK_FENCE.getDefaultState(), 2, 3, 2, structureBoundingBoxIn);
                this.setBlockState(worldIn, Blocks.OAK_FENCE.getDefaultState(), 3, 3, 7, structureBoundingBoxIn);
                this.setBlockState(worldIn, Blocks.AIR.getDefaultState(), 1, 3, 4, structureBoundingBoxIn);
                this.setBlockState(worldIn, Blocks.AIR.getDefaultState(), 5, 3, 4, structureBoundingBoxIn);
                this.setBlockState(worldIn, Blocks.AIR.getDefaultState(), 5, 3, 5, structureBoundingBoxIn);
                this.setBlockState(worldIn, Blocks.FLOWER_POT.getDefaultState().withProperty(BlockFlowerPot.CONTENTS, BlockFlowerPot.EnumFlowerType.MUSHROOM_RED), 1, 3, 5, structureBoundingBoxIn);
                this.setBlockState(worldIn, Blocks.CRAFTING_TABLE.getDefaultState(), 2, 2, 6, structureBoundingBoxIn);
                this.setBlockState(worldIn, Blocks.BREWING_STAND.getDefaultState(), 2, 3, 6, structureBoundingBoxIn);
                
                //following code is a modified version from JavaMan7's youtube tutorial about making structures (But went into detail about how to put potions in brewing stands)
                TileEntity tileentity = worldIn.getTileEntity(new BlockPos(this.getXWithOffset(2, 6), this.getYWithOffset(3), this.getZWithOffset(2, 6)));
                
                if (tileentity instanceof TileEntityBrewingStand)
                {
	               	 int potionSlot = 1 + random.nextInt(3);
	               	 
	               	 for (int j = 0; j < potionSlot; j++) {
	               		 
	               		 int potionType = random.nextInt(9);
	               		
	               		 ItemStack potion=null;
			           	
	               		 //5/9 chance
	               		 if(potionType < 5) {
	               			 potion = new ItemStack(Items.POTIONITEM);PotionUtils.addPotionToItemStack(potion, PotionTypes.STRONG_LEAPING);
	               	 	 }
	               		 //3/9 chance
	               		 else if(potionType < 8) {
	               			 potion = new ItemStack(Items.POTIONITEM);PotionUtils.addPotionToItemStack(potion, PotionTypes.STRONG_POISON); 
	               		 }
	               		 //1/9 chance
	               		 else{
	               			 potion = new ItemStack(Items.POTIONITEM);PotionUtils.addPotionToItemStack(potion, PotionTypes.LONG_NIGHT_VISION);
			           	 }
	               	 
		               	 ((TileEntityBrewingStand)tileentity).setInventorySlotContents(j,potion);
		             }
                }
               	 
               	 
                
                this.setBlockState(worldIn, Blocks.CAULDRON.getDefaultState().withProperty(BlockCauldron.LEVEL, 2), 4, 2, 6, structureBoundingBoxIn);
                this.setBlockState(worldIn, Blocks.OAK_FENCE.getDefaultState(), 1, 2, 1, structureBoundingBoxIn);
                this.setBlockState(worldIn, Blocks.OAK_FENCE.getDefaultState(), 5, 2, 1, structureBoundingBoxIn);
                IBlockState iblockstate = Blocks.SPRUCE_STAIRS.getDefaultState().withProperty(BlockStairs.FACING, EnumFacing.NORTH);
                IBlockState iblockstate1 = Blocks.SPRUCE_STAIRS.getDefaultState().withProperty(BlockStairs.FACING, EnumFacing.EAST);
                IBlockState iblockstate2 = Blocks.SPRUCE_STAIRS.getDefaultState().withProperty(BlockStairs.FACING, EnumFacing.WEST);
                IBlockState iblockstate3 = Blocks.SPRUCE_STAIRS.getDefaultState().withProperty(BlockStairs.FACING, EnumFacing.SOUTH);
                this.fillWithBlocks(worldIn, structureBoundingBoxIn, 0, 4, 1, 6, 4, 1, iblockstate, iblockstate, false);
                this.fillWithBlocks(worldIn, structureBoundingBoxIn, 0, 4, 2, 0, 4, 7, iblockstate1, iblockstate1, false);
                this.fillWithBlocks(worldIn, structureBoundingBoxIn, 6, 4, 2, 6, 4, 7, iblockstate2, iblockstate2, false);
                this.fillWithBlocks(worldIn, structureBoundingBoxIn, 0, 4, 8, 6, 4, 8, iblockstate3, iblockstate3, false);
            	 


                for (int i = 2; i <= 7; i += 5)
                {
                    for (int j = 1; j <= 5; j += 4)
                    {
                        this.replaceAirAndLiquidDownwards(worldIn, Blocks.LOG.getDefaultState(), j, -1, i, structureBoundingBoxIn);
                    }
                }

                if (!this.hasWitch)
                {
                    int l = this.getXWithOffset(2, 5);
                    int i1 = this.getYWithOffset(2);
                    int k = this.getZWithOffset(2, 5);

                    if (structureBoundingBoxIn.isVecInside(new BlockPos(l, i1, k)))
                    {
                        this.hasWitch = true;
                        EntityWitch entitywitch = new EntityWitch(worldIn);
                        entitywitch.enablePersistence();
                        entitywitch.setLocationAndAngles((double)l + 0.5D, (double)i1, (double)k + 0.5D, 0.0F, 0.0F);
                        entitywitch.onInitialSpawn(worldIn.getDifficultyForLocation(new BlockPos(l, i1, k)), (IEntityLivingData)null);
                        worldIn.spawnEntity(entitywitch);
                    }
                }

                return true;
            }
        }
    }
}
